<?xml version="1.0" encoding="UTF-8"?>
<testng-results skipped="0" failed="3" ignored="0" total="5" passed="2">
  <reporter-output>
  </reporter-output>
  <suite name="Functional Suite" duration-ms="10946" started-at="2019-05-01T16:10:42Z" finished-at="2019-05-01T16:10:53Z">
    <groups>
      <group name="functional">
        <method signature="TestCase1.ValidateTitle()[pri:2, instance:TestNG.TestCase1@6a41eaa2]" name="ValidateTitle" class="TestNG.TestCase1"/>
        <method signature="TestCase1.doLogin()[pri:1, instance:TestNG.TestCase1@6a41eaa2]" name="doLogin" class="TestNG.TestCase1"/>
        <method signature="TestCase2.doLogin()[pri:1, instance:TestNG.TestCase2@2f686d1f]" name="doLogin" class="TestNG.TestCase2"/>
      </group> <!-- functional -->
      <group name="smoke">
        <method signature="TestCase1.ValidateTitle()[pri:2, instance:TestNG.TestCase1@6a41eaa2]" name="ValidateTitle" class="TestNG.TestCase1"/>
        <method signature="TestCase2.doLogin()[pri:1, instance:TestNG.TestCase2@2f686d1f]" name="doLogin" class="TestNG.TestCase2"/>
        <method signature="TestCase2.ValidateTitle()[pri:2, instance:TestNG.TestCase2@2f686d1f]" name="ValidateTitle" class="TestNG.TestCase2"/>
      </group> <!-- smoke -->
    </groups>
    <test name="Login Test" duration-ms="6422" started-at="2019-05-01T16:10:42Z" finished-at="2019-05-01T16:10:48Z">
      <class name="TestNG.TestCase1">
        <test-method status="PASS" signature="doLogin()[pri:1, instance:TestNG.TestCase1@6a41eaa2]" name="doLogin" duration-ms="6103" started-at="2019-05-01T16:10:42Z" finished-at="2019-05-01T16:10:48Z">
          <reporter-output>
          </reporter-output>
        </test-method> <!-- doLogin -->
        <test-method status="FAIL" signature="ValidateTitle()[pri:2, instance:TestNG.TestCase1@6a41eaa2]" name="ValidateTitle" duration-ms="27" started-at="2019-05-01T16:10:48Z" finished-at="2019-05-01T16:10:48Z">
          <exception class="java.lang.AssertionError">
            <message>
              <![CDATA[The following asserts failed:
expected [Sign in – Google accounts] but found [accounts.google.com]]]>
            </message>
            <full-stacktrace>
              <![CDATA[java.lang.AssertionError: The following asserts failed:
expected [Sign in – Google accounts] but found [accounts.google.com]
at org.testng.asserts.SoftAssert.assertAll(SoftAssert.java:43)
at TestNG.TestCase1.ValidateTitle(TestCase1.java:30)
at sun.reflect.NativeMethodAccessorImpl.invoke0(Native Method)
at sun.reflect.NativeMethodAccessorImpl.invoke(NativeMethodAccessorImpl.java:62)
at sun.reflect.DelegatingMethodAccessorImpl.invoke(DelegatingMethodAccessorImpl.java:43)
at java.lang.reflect.Method.invoke(Method.java:498)
at org.testng.internal.MethodInvocationHelper.invokeMethod(MethodInvocationHelper.java:124)
at org.testng.internal.Invoker.invokeMethod(Invoker.java:583)
at org.testng.internal.Invoker.invokeTestMethod(Invoker.java:719)
at org.testng.internal.Invoker.invokeTestMethods(Invoker.java:989)
at org.testng.internal.TestMethodWorker.invokeTestMethods(TestMethodWorker.java:125)
at org.testng.internal.TestMethodWorker.run(TestMethodWorker.java:109)
at org.testng.TestRunner.privateRun(TestRunner.java:648)
at org.testng.TestRunner.run(TestRunner.java:505)
at org.testng.SuiteRunner.runTest(SuiteRunner.java:455)
at org.testng.SuiteRunner.runSequentially(SuiteRunner.java:450)
at org.testng.SuiteRunner.privateRun(SuiteRunner.java:415)
at org.testng.SuiteRunner.run(SuiteRunner.java:364)
at org.testng.SuiteRunnerWorker.runSuite(SuiteRunnerWorker.java:52)
at org.testng.SuiteRunnerWorker.run(SuiteRunnerWorker.java:84)
at org.testng.TestNG.runSuitesSequentially(TestNG.java:1208)
at org.testng.TestNG.runSuitesLocally(TestNG.java:1137)
at org.testng.TestNG.runSuites(TestNG.java:1049)
at org.testng.TestNG.run(TestNG.java:1017)
at org.testng.remote.AbstractRemoteTestNG.run(AbstractRemoteTestNG.java:115)
at org.testng.remote.RemoteTestNG.initAndRun(RemoteTestNG.java:251)
at org.testng.remote.RemoteTestNG.main(RemoteTestNG.java:77)
]]>
            </full-stacktrace>
          </exception> <!-- java.lang.AssertionError -->
          <reporter-output>
          </reporter-output>
        </test-method> <!-- ValidateTitle -->
        <test-method status="PASS" signature="closeee()[pri:0, instance:TestNG.TestCase1@6a41eaa2]" name="closeee" is-config="true" duration-ms="253" started-at="2019-05-01T16:10:48Z" finished-at="2019-05-01T16:10:48Z">
          <reporter-output>
          </reporter-output>
        </test-method> <!-- closeee -->
      </class> <!-- TestNG.TestCase1 -->
    </test> <!-- Login Test -->
    <test name="Validate Title" duration-ms="4330" started-at="2019-05-01T16:10:48Z" finished-at="2019-05-01T16:10:53Z">
      <class name="TestNG.TestCase2">
        <test-method status="PASS" signature="doLogin()[pri:1, instance:TestNG.TestCase2@2f686d1f]" name="doLogin" duration-ms="4267" started-at="2019-05-01T16:10:48Z" finished-at="2019-05-01T16:10:53Z">
          <reporter-output>
          </reporter-output>
        </test-method> <!-- doLogin -->
        <test-method status="FAIL" signature="ValidateTitle()[pri:2, instance:TestNG.TestCase2@2f686d1f]" name="ValidateTitle" duration-ms="57" started-at="2019-05-01T16:10:53Z" depends-on-methods="TestNG.TestCase2.doLogin" finished-at="2019-05-01T16:10:53Z">
          <exception class="java.lang.AssertionError">
            <message>
              <![CDATA[The following asserts failed:
expected [Sign in – Google accounts] but found [accounts.google.com]]]>
            </message>
            <full-stacktrace>
              <![CDATA[java.lang.AssertionError: The following asserts failed:
expected [Sign in – Google accounts] but found [accounts.google.com]
at org.testng.asserts.SoftAssert.assertAll(SoftAssert.java:43)
at TestNG.TestCase2.ValidateTitle(TestCase2.java:33)
at sun.reflect.NativeMethodAccessorImpl.invoke0(Native Method)
at sun.reflect.NativeMethodAccessorImpl.invoke(NativeMethodAccessorImpl.java:62)
at sun.reflect.DelegatingMethodAccessorImpl.invoke(DelegatingMethodAccessorImpl.java:43)
at java.lang.reflect.Method.invoke(Method.java:498)
at org.testng.internal.MethodInvocationHelper.invokeMethod(MethodInvocationHelper.java:124)
at org.testng.internal.Invoker.invokeMethod(Invoker.java:583)
at org.testng.internal.Invoker.invokeTestMethod(Invoker.java:719)
at org.testng.internal.Invoker.invokeTestMethods(Invoker.java:989)
at org.testng.internal.TestMethodWorker.invokeTestMethods(TestMethodWorker.java:125)
at org.testng.internal.TestMethodWorker.run(TestMethodWorker.java:109)
at org.testng.TestRunner.privateRun(TestRunner.java:648)
at org.testng.TestRunner.run(TestRunner.java:505)
at org.testng.SuiteRunner.runTest(SuiteRunner.java:455)
at org.testng.SuiteRunner.runSequentially(SuiteRunner.java:450)
at org.testng.SuiteRunner.privateRun(SuiteRunner.java:415)
at org.testng.SuiteRunner.run(SuiteRunner.java:364)
at org.testng.SuiteRunnerWorker.runSuite(SuiteRunnerWorker.java:52)
at org.testng.SuiteRunnerWorker.run(SuiteRunnerWorker.java:84)
at org.testng.TestNG.runSuitesSequentially(TestNG.java:1208)
at org.testng.TestNG.runSuitesLocally(TestNG.java:1137)
at org.testng.TestNG.runSuites(TestNG.java:1049)
at org.testng.TestNG.run(TestNG.java:1017)
at org.testng.remote.AbstractRemoteTestNG.run(AbstractRemoteTestNG.java:115)
at org.testng.remote.RemoteTestNG.initAndRun(RemoteTestNG.java:251)
at org.testng.remote.RemoteTestNG.main(RemoteTestNG.java:77)
]]>
            </full-stacktrace>
          </exception> <!-- java.lang.AssertionError -->
          <reporter-output>
          </reporter-output>
        </test-method> <!-- ValidateTitle -->
      </class> <!-- TestNG.TestCase2 -->
    </test> <!-- Validate Title -->
    <test name="failing Testcase" duration-ms="10" started-at="2019-05-01T16:10:53Z" finished-at="2019-05-01T16:10:53Z">
      <class name="TestNG.TestFailure">
        <test-method status="PASS" signature="setup()[pri:0, instance:TestNG.TestFailure@3f49dace]" name="setup" is-config="true" duration-ms="32" started-at="2019-05-01T16:10:42Z" finished-at="2019-05-01T16:10:42Z">
          <reporter-output>
          </reporter-output>
        </test-method> <!-- setup -->
        <test-method status="FAIL" signature="doLogin()[pri:0, instance:TestNG.TestFailure@3f49dace]" name="doLogin" duration-ms="3" started-at="2019-05-01T16:10:53Z" finished-at="2019-05-01T16:10:53Z">
          <exception class="java.lang.AssertionError">
            <message>
              <![CDATA[Failing the login test]]>
            </message>
            <full-stacktrace>
              <![CDATA[java.lang.AssertionError: Failing the login test
at org.testng.Assert.fail(Assert.java:96)
at TestNG.TestFailure.doLogin(TestFailure.java:9)
at sun.reflect.NativeMethodAccessorImpl.invoke0(Native Method)
at sun.reflect.NativeMethodAccessorImpl.invoke(NativeMethodAccessorImpl.java:62)
at sun.reflect.DelegatingMethodAccessorImpl.invoke(DelegatingMethodAccessorImpl.java:43)
at java.lang.reflect.Method.invoke(Method.java:498)
at org.testng.internal.MethodInvocationHelper.invokeMethod(MethodInvocationHelper.java:124)
at org.testng.internal.Invoker.invokeMethod(Invoker.java:583)
at org.testng.internal.Invoker.invokeTestMethod(Invoker.java:719)
at org.testng.internal.Invoker.invokeTestMethods(Invoker.java:989)
at org.testng.internal.TestMethodWorker.invokeTestMethods(TestMethodWorker.java:125)
at org.testng.internal.TestMethodWorker.run(TestMethodWorker.java:109)
at org.testng.TestRunner.privateRun(TestRunner.java:648)
at org.testng.TestRunner.run(TestRunner.java:505)
at org.testng.SuiteRunner.runTest(SuiteRunner.java:455)
at org.testng.SuiteRunner.runSequentially(SuiteRunner.java:450)
at org.testng.SuiteRunner.privateRun(SuiteRunner.java:415)
at org.testng.SuiteRunner.run(SuiteRunner.java:364)
at org.testng.SuiteRunnerWorker.runSuite(SuiteRunnerWorker.java:52)
at org.testng.SuiteRunnerWorker.run(SuiteRunnerWorker.java:84)
at org.testng.TestNG.runSuitesSequentially(TestNG.java:1208)
at org.testng.TestNG.runSuitesLocally(TestNG.java:1137)
at org.testng.TestNG.runSuites(TestNG.java:1049)
at org.testng.TestNG.run(TestNG.java:1017)
at org.testng.remote.AbstractRemoteTestNG.run(AbstractRemoteTestNG.java:115)
at org.testng.remote.RemoteTestNG.initAndRun(RemoteTestNG.java:251)
at org.testng.remote.RemoteTestNG.main(RemoteTestNG.java:77)
]]>
            </full-stacktrace>
          </exception> <!-- java.lang.AssertionError -->
          <reporter-output>
          </reporter-output>
        </test-method> <!-- doLogin -->
        <test-method status="PASS" signature="quit()[pri:0, instance:TestNG.TestFailure@3f49dace]" name="quit" is-config="true" duration-ms="0" started-at="2019-05-01T16:10:53Z" finished-at="2019-05-01T16:10:53Z">
          <reporter-output>
          </reporter-output>
        </test-method> <!-- quit -->
      </class> <!-- TestNG.TestFailure -->
    </test> <!-- failing Testcase -->
  </suite> <!-- Functional Suite -->
</testng-results>
