<?xml version="1.0" encoding="UTF-8"?>
<testng-results skipped="1" failed="2" ignored="0" total="4" passed="1">
  <reporter-output>
  </reporter-output>
  <suite name="Functional Suite" duration-ms="39114" started-at="2019-04-25T16:50:33Z" finished-at="2019-04-25T16:51:12Z">
    <groups>
    </groups>
    <test name="Login Test" duration-ms="28032" started-at="2019-04-25T16:50:33Z" finished-at="2019-04-25T16:51:01Z">
      <class name="TestNG.TestCase1">
        <test-method status="PASS" signature="doLogin()[pri:1, instance:TestNG.TestCase1@91161c7]" name="doLogin" duration-ms="27450" started-at="2019-04-25T16:50:33Z" finished-at="2019-04-25T16:51:01Z">
          <reporter-output>
          </reporter-output>
        </test-method> <!-- doLogin -->
        <test-method status="FAIL" signature="ValidateTitle()[pri:2, instance:TestNG.TestCase1@91161c7]" name="ValidateTitle" duration-ms="41" started-at="2019-04-25T16:51:01Z" finished-at="2019-04-25T16:51:01Z">
          <exception class="java.lang.AssertionError">
            <message>
              <![CDATA[The following asserts failed:
expected [Sign in – Google accounts1] but found [Sign in – Google accounts]]]>
            </message>
            <full-stacktrace>
              <![CDATA[java.lang.AssertionError: The following asserts failed:
expected [Sign in – Google accounts1] but found [Sign in – Google accounts]
at org.testng.asserts.SoftAssert.assertAll(SoftAssert.java:43)
at TestNG.TestCase1.ValidateTitle(TestCase1.java:30)
at sun.reflect.NativeMethodAccessorImpl.invoke0(Native Method)
at sun.reflect.NativeMethodAccessorImpl.invoke(NativeMethodAccessorImpl.java:62)
at sun.reflect.DelegatingMethodAccessorImpl.invoke(DelegatingMethodAccessorImpl.java:43)
at java.lang.reflect.Method.invoke(Method.java:498)
at org.testng.internal.MethodInvocationHelper.invokeMethod(MethodInvocationHelper.java:124)
at org.testng.internal.Invoker.invokeMethod(Invoker.java:583)
at org.testng.internal.Invoker.invokeTestMethod(Invoker.java:719)
at org.testng.internal.Invoker.invokeTestMethods(Invoker.java:989)
at org.testng.internal.TestMethodWorker.invokeTestMethods(TestMethodWorker.java:125)
at org.testng.internal.TestMethodWorker.run(TestMethodWorker.java:109)
at org.testng.TestRunner.privateRun(TestRunner.java:648)
at org.testng.TestRunner.run(TestRunner.java:505)
at org.testng.SuiteRunner.runTest(SuiteRunner.java:455)
at org.testng.SuiteRunner.runSequentially(SuiteRunner.java:450)
at org.testng.SuiteRunner.privateRun(SuiteRunner.java:415)
at org.testng.SuiteRunner.run(SuiteRunner.java:364)
at org.testng.SuiteRunnerWorker.runSuite(SuiteRunnerWorker.java:52)
at org.testng.SuiteRunnerWorker.run(SuiteRunnerWorker.java:84)
at org.testng.TestNG.runSuitesSequentially(TestNG.java:1208)
at org.testng.TestNG.runSuitesLocally(TestNG.java:1137)
at org.testng.TestNG.runSuites(TestNG.java:1049)
at org.testng.TestNG.run(TestNG.java:1017)
at org.testng.remote.AbstractRemoteTestNG.run(AbstractRemoteTestNG.java:115)
at org.testng.remote.RemoteTestNG.initAndRun(RemoteTestNG.java:251)
at org.testng.remote.RemoteTestNG.main(RemoteTestNG.java:77)
]]>
            </full-stacktrace>
          </exception> <!-- java.lang.AssertionError -->
          <reporter-output>
          </reporter-output>
        </test-method> <!-- ValidateTitle -->
        <test-method status="PASS" signature="closeee()[pri:0, instance:TestNG.TestCase1@91161c7]" name="closeee" is-config="true" duration-ms="425" started-at="2019-04-25T16:51:01Z" finished-at="2019-04-25T16:51:01Z">
          <reporter-output>
          </reporter-output>
        </test-method> <!-- closeee -->
      </class> <!-- TestNG.TestCase1 -->
    </test> <!-- Login Test -->
    <test name="Validate Title" duration-ms="10519" started-at="2019-04-25T16:51:02Z" finished-at="2019-04-25T16:51:12Z">
      <class name="TestNG.TestCase2">
        <test-method status="FAIL" signature="doLogin()[pri:1, instance:TestNG.TestCase2@6500df86]" name="doLogin" duration-ms="10491" started-at="2019-04-25T16:51:02Z" finished-at="2019-04-25T16:51:12Z">
          <exception class="java.lang.AssertionError">
            <message>
              <![CDATA[user not logged in successfully]]>
            </message>
            <full-stacktrace>
              <![CDATA[java.lang.AssertionError: user not logged in successfully
at org.testng.Assert.fail(Assert.java:96)
at TestNG.TestCase2.doLogin(TestCase2.java:19)
at sun.reflect.NativeMethodAccessorImpl.invoke0(Native Method)
at sun.reflect.NativeMethodAccessorImpl.invoke(NativeMethodAccessorImpl.java:62)
at sun.reflect.DelegatingMethodAccessorImpl.invoke(DelegatingMethodAccessorImpl.java:43)
at java.lang.reflect.Method.invoke(Method.java:498)
at org.testng.internal.MethodInvocationHelper.invokeMethod(MethodInvocationHelper.java:124)
at org.testng.internal.Invoker.invokeMethod(Invoker.java:583)
at org.testng.internal.Invoker.invokeTestMethod(Invoker.java:719)
at org.testng.internal.Invoker.invokeTestMethods(Invoker.java:989)
at org.testng.internal.TestMethodWorker.invokeTestMethods(TestMethodWorker.java:125)
at org.testng.internal.TestMethodWorker.run(TestMethodWorker.java:109)
at org.testng.TestRunner.privateRun(TestRunner.java:648)
at org.testng.TestRunner.run(TestRunner.java:505)
at org.testng.SuiteRunner.runTest(SuiteRunner.java:455)
at org.testng.SuiteRunner.runSequentially(SuiteRunner.java:450)
at org.testng.SuiteRunner.privateRun(SuiteRunner.java:415)
at org.testng.SuiteRunner.run(SuiteRunner.java:364)
at org.testng.SuiteRunnerWorker.runSuite(SuiteRunnerWorker.java:52)
at org.testng.SuiteRunnerWorker.run(SuiteRunnerWorker.java:84)
at org.testng.TestNG.runSuitesSequentially(TestNG.java:1208)
at org.testng.TestNG.runSuitesLocally(TestNG.java:1137)
at org.testng.TestNG.runSuites(TestNG.java:1049)
at org.testng.TestNG.run(TestNG.java:1017)
at org.testng.remote.AbstractRemoteTestNG.run(AbstractRemoteTestNG.java:115)
at org.testng.remote.RemoteTestNG.initAndRun(RemoteTestNG.java:251)
at org.testng.remote.RemoteTestNG.main(RemoteTestNG.java:77)
]]>
            </full-stacktrace>
          </exception> <!-- java.lang.AssertionError -->
          <reporter-output>
          </reporter-output>
        </test-method> <!-- doLogin -->
        <test-method status="SKIP" signature="ValidateTitle()[pri:2, instance:TestNG.TestCase2@6500df86]" name="ValidateTitle" duration-ms="1" started-at="2019-04-25T16:51:12Z" depends-on-methods="TestNG.TestCase2.doLogin" finished-at="2019-04-25T16:51:12Z">
          <exception class="java.lang.Throwable">
            <message>
              <![CDATA[Method TestCase2.ValidateTitle()[pri:2, instance:TestNG.TestCase2@6500df86] depends on not successfully finished methods]]>
            </message>
            <full-stacktrace>
              <![CDATA[java.lang.Throwable: Method TestCase2.ValidateTitle()[pri:2, instance:TestNG.TestCase2@6500df86] depends on not successfully finished methods
at org.testng.internal.Invoker.invokeTestMethods(Invoker.java:888)
at org.testng.internal.TestMethodWorker.invokeTestMethods(TestMethodWorker.java:125)
at org.testng.internal.TestMethodWorker.run(TestMethodWorker.java:109)
at org.testng.TestRunner.privateRun(TestRunner.java:648)
at org.testng.TestRunner.run(TestRunner.java:505)
at org.testng.SuiteRunner.runTest(SuiteRunner.java:455)
at org.testng.SuiteRunner.runSequentially(SuiteRunner.java:450)
at org.testng.SuiteRunner.privateRun(SuiteRunner.java:415)
at org.testng.SuiteRunner.run(SuiteRunner.java:364)
at org.testng.SuiteRunnerWorker.runSuite(SuiteRunnerWorker.java:52)
at org.testng.SuiteRunnerWorker.run(SuiteRunnerWorker.java:84)
at org.testng.TestNG.runSuitesSequentially(TestNG.java:1208)
at org.testng.TestNG.runSuitesLocally(TestNG.java:1137)
at org.testng.TestNG.runSuites(TestNG.java:1049)
at org.testng.TestNG.run(TestNG.java:1017)
at org.testng.remote.AbstractRemoteTestNG.run(AbstractRemoteTestNG.java:115)
at org.testng.remote.RemoteTestNG.initAndRun(RemoteTestNG.java:251)
at org.testng.remote.RemoteTestNG.main(RemoteTestNG.java:77)
]]>
            </full-stacktrace>
          </exception> <!-- java.lang.Throwable -->
          <reporter-output>
          </reporter-output>
        </test-method> <!-- ValidateTitle -->
      </class> <!-- TestNG.TestCase2 -->
    </test> <!-- Validate Title -->
  </suite> <!-- Functional Suite -->
</testng-results>
